<?xml version="1.0" encoding="utf-8"?>
<!-- This URDF was automatically created by SolidWorks to URDF Exporter! Originally created by Stephen Brawner (brawner@gmail.com) 
     Commit Version: 1.6.0-1-g15f4949  Build Version: 1.6.7594.29634
     For more information, please see http://wiki.ros.org/sw_urdf_exporter -->
<robot
  name="어셈블리1">
  <link
    name="base_link">
    <inertial>
      <origin
        xyz="-0.0132871229028094 -0.0190872156314789 -0.0165094953014788"
        rpy="0 0 0" />
      <mass
        value="3.79600627082132" />
      <inertia
        ixx="0.00950873308951061"
        ixy="-4.41730297888478E-05"
        ixz="-0.000344061860957029"
        iyy="0.015823556089242"
        iyz="-0.000165763768209665"
        izz="0.00921479103261655" />
    </inertial>
    <visual>
      <origin
        xyz="0 0 0"
        rpy="0 0 0" />
      <geometry>
        <mesh
          filename="package://어셈블리1/meshes/base_link.STL" />
      </geometry>
      <material
        name="">
        <color
          rgba="0.792156862745098 0.819607843137255 0.933333333333333 1" />
      </material>
    </visual>
    <collision>
      <origin
        xyz="0 0 0"
        rpy="0 0 0" />
      <geometry>
        <mesh
          filename="package://어셈블리1/meshes/base_link.STL" />
      </geometry>
    </collision>
  </link>
  <link
    name="opencr_link">
    <inertial>
      <origin
        xyz="0.0180007095539802 -0.018114560187332 -0.00970352267675567"
        rpy="0 0 0" />
      <mass
        value="5.55801093857231" />
      <inertia
        ixx="0.0702910169590417"
        ixy="0.00177365412889999"
        ixz="-0.00174438824817206"
        iyy="0.0556214725394112"
        iyz="7.33898971713756E-05"
        izz="0.0859284870938966" />
    </inertial>
    <visual>
      <origin
        xyz="0 0 0"
        rpy="0 0 0" />
      <geometry>
        <mesh
          filename="package://어셈블리1/meshes/opencr_link.STL" />
      </geometry>
      <material
        name="">
        <color
          rgba="0.792156862745098 0.819607843137255 0.933333333333333 1" />
      </material>
    </visual>
    <collision>
      <origin
        xyz="0 0 0"
        rpy="0 0 0" />
      <geometry>
        <mesh
          filename="package://어셈블리1/meshes/opencr_link.STL" />
      </geometry>
    </collision>
  </link>
  <joint
    name="opencr_joint"
    type="fixed">
    <origin
      xyz="0 0 0"
      rpy="0 0 -3.1416" />
    <parent
      link="base_link" />
    <child
      link="opencr_link" />
    <axis
      xyz="0 0 0" />
  </joint>
  <link
    name="lidar_link">
    <inertial>
      <origin
        xyz="1.3394E-08 1.1116E-09 0.029386"
        rpy="0 0 0" />
      <mass
        value="0.13177" />
      <inertia
        ixx="6.9567E-05"
        ixy="-9.5937E-12"
        ixz="-5.2972E-11"
        iyy="6.9567E-05"
        iyz="-4.3961E-12"
        izz="4.4764E-05" />
    </inertial>
    <visual>
      <origin
        xyz="0 0 0"
        rpy="0 0 0" />
      <geometry>
        <mesh
          filename="package://어셈블리1/meshes/lidar_link.STL" />
      </geometry>
      <material
        name="">
        <color
          rgba="0.79216 0.81961 0.93333 1" />
      </material>
    </visual>
    <collision>
      <origin
        xyz="0 0 0"
        rpy="0 0 0" />
      <geometry>
        <mesh
          filename="package://어셈블리1/meshes/lidar_link.STL" />
      </geometry>
    </collision>
  </link>
  <joint
    name="lidar_joint"
    type="fixed">
    <origin
      xyz="-0.035043 0.0083315 0.077"
      rpy="0 0 0" />
    <parent
      link="base_link" />
    <child
      link="lidar_link" />
    <axis
      xyz="0 0 0" />
  </joint>
  <link
    name="camera_link">
    <inertial>
      <origin
        xyz="-6.5919E-17 -2.4587E-10 0.0165"
        rpy="0 0 0" />
      <mass
        value="0.16688" />
      <inertia
        ixx="2.7222E-05"
        ixy="-2.5726E-19"
        ixz="-3.9561E-19"
        iyy="0.00041211"
        iyz="4.5682E-14"
        izz="0.00040904" />
    </inertial>
    <visual>
      <origin
        xyz="0 0 0"
        rpy="0 0 0" />
      <geometry>
        <mesh
          filename="package://어셈블리1/meshes/camera_link.STL" />
      </geometry>
      <material
        name="">
        <color
          rgba="0.79216 0.81961 0.93333 1" />
      </material>
    </visual>
    <collision>
      <origin
        xyz="0 0 0"
        rpy="0 0 0" />
      <geometry>
        <mesh
          filename="package://어셈블리1/meshes/camera_link.STL" />
      </geometry>
    </collision>
  </link>
  <joint
    name="camera_joint"
    type="fixed">
    <origin
      xyz="-0.13404 0.0083315 0.092"
      rpy="-1.5708 0 1.5708" />
    <parent
      link="base_link" />
    <child
      link="camera_link" />
    <axis
      xyz="0 0 0" />
  </joint>
  <link
    name="left_wheel_link">
    <inertial>
      <origin
        xyz="-4.54497550705923E-16 1.79717352111197E-15 0.0145"
        rpy="0 0 0" />
      <mass
        value="0.431849530870227" />
      <inertia
        ixx="0.000547310482911071"
        ixy="-8.13151629364128E-20"
        ixz="-5.76064820844141E-20"
        iyy="0.000547310482911071"
        iyz="1.70985068972411E-19"
        izz="0.00103898710950625" />
    </inertial>
    <visual>
      <origin
        xyz="0 0 0"
        rpy="0 0 0" />
      <geometry>
        <mesh
          filename="package://어셈블리1/meshes/left_wheel_link.STL" />
      </geometry>
      <material
        name="">
        <color
          rgba="0.792156862745098 0.819607843137255 0.933333333333333 1" />
      </material>
    </visual>
    <collision>
      <origin
        xyz="0 0 0"
        rpy="0 0 0" />
      <geometry>
        <mesh
          filename="package://어셈블리1/meshes/left_wheel_link.STL" />
      </geometry>
    </collision>
  </link>
  <joint
    name="left_wheel_joint"
    type="continuous">
    <origin
      xyz="0.027457 -0.12147 -0.0339"
      rpy="-1.5708 0.62286 -3.1416" />
    <parent
      link="base_link" />
    <child
      link="left_wheel_link" />
    <axis
      xyz="0 0 1" />
  </joint>
  <link
    name="right_wheel_link">
    <inertial>
      <origin
        xyz="1.40859546249317E-15 7.97972798949331E-16 -0.0145000000000001"
        rpy="0 0 0" />
      <mass
        value="0.431849530870227" />
      <inertia
        ixx="0.000547310482911071"
        ixy="-8.470329472543E-22"
        ixz="2.71760685640883E-19"
        iyy="0.000547310482911071"
        iyz="-6.44834273233266E-19"
        izz="0.00103898710950625" />
    </inertial>
    <visual>
      <origin
        xyz="0 0 0"
        rpy="0 0 0" />
      <geometry>
        <mesh
          filename="package://어셈블리1/meshes/right_wheel_link.STL" />
      </geometry>
      <material
        name="">
        <color
          rgba="0.792156862745098 0.819607843137255 0.933333333333333 1" />
      </material>
    </visual>
    <collision>
      <origin
        xyz="0 0 0"
        rpy="0 0 0" />
      <geometry>
        <mesh
          filename="package://어셈블리1/meshes/right_wheel_link.STL" />
      </geometry>
    </collision>
  </link>
  <joint
    name="right_wheel_joint"
    type="continuous">
    <origin
      xyz="0.027457 0.13813 -0.0339"
      rpy="1.5708 -0.0072638 0" />
    <parent
      link="base_link" />
    <child
      link="right_wheel_link" />
    <axis
      xyz="0 0 1" />
  </joint>
  <link
    name="front_link">
    <inertial>
      <origin
        xyz="-0.102550444822188 0.0186362763099482 -0.0499420238037555"
        rpy="0 0 0" />
      <mass
        value="0.273534418315027" />
      <inertia
        ixx="0.00033404367279413"
        ixy="-5.02928734296123E-07"
        ixz="1.34776273983535E-06"
        iyy="0.000793983435909688"
        iyz="6.47618301935972E-05"
        izz="0.000552792585022654" />
    </inertial>
    <visual>
      <origin
        xyz="0 0 0"
        rpy="0 0 0" />
      <geometry>
        <mesh
          filename="package://어셈블리1/meshes/front_link.STL" />
      </geometry>
      <material
        name="">
        <color
          rgba="0.792156862745098 0.819607843137255 0.933333333333333 1" />
      </material>
    </visual>
    <collision>
      <origin
        xyz="0 0 0"
        rpy="0 0 0" />
      <geometry>
        <mesh
          filename="package://어셈블리1/meshes/front_link.STL" />
      </geometry>
    </collision>
  </link>
  <joint
    name="front_joint"
    type="revolute">
    <origin
      xyz="-0.15554 0 -0.06"
      rpy="2.7286 0 -1.5708" />
    <parent
      link="base_link" />
    <child
      link="front_link" />
    <axis
      xyz="1 0 0" />
    <limit
      lower="0"
      upper="0"
      effort="0"
      velocity="0" />
  </joint>
  <link
    name="feed_link">
    <inertial>
      <origin
        xyz="-0.0165698438786769 2.44249065417534E-15 0.000749999999999952"
        rpy="0 0 0" />
      <mass
        value="0.00143426215563702" />
      <inertia
        ixx="5.89380670397772E-08"
        ixy="3.03575115170312E-20"
        ixz="-5.94102382536487E-22"
        iyy="2.65747442341081E-07"
        iyz="-5.26615014644146E-23"
        izz="3.24147661072495E-07" />
    </inertial>
    <visual>
      <origin
        xyz="0 0 0"
        rpy="0 0 0" />
      <geometry>
        <mesh
          filename="package://어셈블리1/meshes/feed_link.STL" />
      </geometry>
      <material
        name="">
        <color
          rgba="0.792156862745098 0.819607843137255 0.933333333333333 1" />
      </material>
    </visual>
    <collision>
      <origin
        xyz="0 0 0"
        rpy="0 0 0" />
      <geometry>
        <mesh
          filename="package://어셈블리1/meshes/feed_link.STL" />
      </geometry>
    </collision>
  </link>
  <joint
    name="feed_joint"
    type="revolute">
    <origin
      xyz="0.055457 -0.053668 0.0483"
      rpy="0 0 -1.5706" />
    <parent
      link="base_link" />
    <child
      link="feed_link" />
    <axis
      xyz="0 0 1" />
    <limit
      lower="0"
      upper="0"
      effort="0"
      velocity="0" />
  </joint>
  <link
    name="back_link">
    <inertial>
      <origin
        xyz="-0.00159581425708959 -0.00219319750044118 -0.0452663377943654"
        rpy="0 0 0" />
      <mass
        value="0.123674446484502" />
      <inertia
        ixx="0.000154119408139331"
        ixy="-1.99217286118724E-07"
        ixz="-4.10671960339738E-06"
        iyy="0.0003923074275057"
        iyz="-1.15250552157468E-05"
        izz="0.000264072633501366" />
    </inertial>
    <visual>
      <origin
        xyz="0 0 0"
        rpy="0 0 0" />
      <geometry>
        <mesh
          filename="package://어셈블리1/meshes/back_link.STL" />
      </geometry>
      <material
        name="">
        <color
          rgba="0.792156862745098 0.819607843137255 0.933333333333333 1" />
      </material>
    </visual>
    <collision>
      <origin
        xyz="0 0 0"
        rpy="0 0 0" />
      <geometry>
        <mesh
          filename="package://어셈블리1/meshes/back_link.STL" />
      </geometry>
    </collision>
  </link>
  <joint
    name="back_joint"
    type="revolute">
    <origin
      xyz="0.085457 0 -0.06"
      rpy="-3.1275 0 -1.5708" />
    <parent
      link="base_link" />
    <child
      link="back_link" />
    <axis
      xyz="1 0 0" />
    <limit
      lower="0"
      upper="0"
      effort="0"
      velocity="0" />
  </joint>
</robot>